<?xml version="1.0" encoding="utf-8"?>
<!-- =================================================================================== -->
<!-- |    This document was autogenerated by xacro from johnny5.urdf.xacro             | -->
<!-- |    EDITING THIS FILE BY HAND IS NOT RECOMMENDED                                 | -->
<!-- =================================================================================== -->
<robot name="johnny5" xmlns:controller="http://playerstage.sourceforge.net/gazebo/xmlschema/#controller" xmlns:gazebo="http://playerstage.sourceforge.net/gazebo/xmlschema/#gz" xmlns:interface="http://playerstage.sourceforge.net/gazebo/xmlschema/#interface" xmlns:xacro="http://ros.org/wiki/xacro">
  <material name="Blue">
    <color rgba="0.0 0.0 0.8 1.0"/>
  </material>
  <material name="Green">
    <color rgba="0.0 0.8 0.0 1.0"/>
  </material>
  <material name="Grey">
    <color rgba="0.7 0.7 0.7 1.0"/>
  </material>
  <material name="Grey2">
    <color rgba="0.9 0.9 0.9 1.0"/>
  </material>
  <material name="Red">
    <color rgba="0.8 0.0 0.0 1.0"/>
  </material>
  <material name="White">
    <color rgba="1.0 1.0 1.0 1.0"/>
  </material>
  <material name="Black">
    <color rgba="0.15 0.15 0.15 1.0"/>
  </material>
  <material name="LightGrey">
    <color rgba="0.6 0.6 0.6 1.0"/>
  </material>
  <link name="base_footprint">
    <inertial>
      <mass value="0.0001"/>
      <origin xyz="0 0 0"/>
      <inertia ixx="0.0001" ixy="0.0" ixz="0.0" iyy="0.0001" iyz="0.0" izz="0.0001"/>
    </inertial>
    <visual>
      <origin rpy="0 0 0" xyz="0 0 0"/>
      <geometry>
        <box size="0.001 0.001 0.001"/>
      </geometry>
      <material name="Green"/>
    </visual>
    <collision>
      <origin rpy="0 0 0" xyz="0 0 0.017"/>
      <geometry>
        <box size="0.001 0.001 0.001"/>
      </geometry>
    </collision>
  </link>
  <link name="base_link">
    <inertial>
      <mass value="2"/>
      <origin xyz="0 0 0"/>
      <inertia ixx="0.01" ixy="0.0" ixz="0.0" iyy="0.01" iyz="0.0" izz="0.01"/>
    </inertial>
    <visual>
      <origin rpy="0 0 0" xyz="0 0 0.0015875"/>
      <geometry>
        <box size="0.206375 0.18415 0.003175"/>
      </geometry>
      <material name="Black"/>
    </visual>
    <collision>
      <origin rpy="0 0 0" xyz="0 0 0.0015875"/>
      <geometry>
        <box size="0.206375 0.18415 0.003175"/>
      </geometry>
    </collision>
  </link>
  <joint name="base_footprint_joint" type="fixed">
    <origin rpy="0 0 0" xyz="0 0 0.0254"/>
    <parent link="base_footprint"/>
    <child link="base_link"/>
  </joint>
  <gazebo reference="base_link">
    <material value="Gazebo/Grey"/>
  </gazebo>
  <link name="deck_link">
    <inertial>
      <mass value="2"/>
      <origin xyz="0 0 0"/>
      <inertia ixx="0.01" ixy="0.0" ixz="0.0" iyy="0.01" iyz="0.0" izz="0.01"/>
    </inertial>
    <visual>
      <origin rpy="0 0 0" xyz="0 0 0.0015875"/>
      <geometry>
        <box size="0.206375 0.18415 0.003175"/>
      </geometry>
      <material name="Black"/>
    </visual>
    <collision>
      <origin rpy="0 0 0" xyz="0 0 0.0015875"/>
      <geometry>
        <box size="0.206375 0.18415 0.003175"/>
      </geometry>
    </collision>
  </link>
  <joint name="deck_joint" type="fixed">
    <origin rpy="0 0 0" xyz="0 0 0.041275"/>
    <parent link="base_link"/>
    <child link="deck_link"/>
  </joint>
  <gazebo reference="deck_link">
    <material value="Gazebo/Grey"/>
  </gazebo>
  <link name="left_track_link">
    <inertial>
      <mass value="1"/>
      <origin xyz="0 0 0"/>
      <inertia ixx="0.01" ixy="0.0" ixz="0.0" iyy="0.01" iyz="0.0" izz="0.01"/>
    </inertial>
    <visual>
      <origin rpy="0 0 0" xyz="0 0 0"/>
      <geometry>
        <box size="0.22225 0.0508 0.09525"/>
      </geometry>
      <material name="Black"/>
    </visual>
    <collision>
      <origin rpy="0 0 0" xyz="0 0 0"/>
      <geometry>
        <box size="0.22225 0.0508 0.09525"/>
      </geometry>
    </collision>
  </link>
  <joint name="left_track_joint" type="fixed">
    <origin rpy="0 0 0" xyz="0.0428625 0.117475 0.041275"/>
    <parent link="base_link"/>
    <child link="left_track_link"/>
  </joint>
  <gazebo reference="left_track_link">
    <material value="Gazebo/Grey"/>
  </gazebo>
  <link name="left_track_front_wheel_link">
    <inertial>
      <mass value="0.1"/>
      <origin xyz="0 0 0"/>
      <inertia ixx="0.001" ixy="0.0" ixz="0.0" iyy="0.001" iyz="0.0" izz="0.001"/>
    </inertial>
    <visual>
      <origin rpy="1.57079632679 0 0" xyz="0 0 0"/>
      <geometry>
        <cylinder length="0.04445" radius="0.0381"/>
      </geometry>
      <material name="White"/>
    </visual>
    <collision>
      <origin rpy="1.57079632679 0 0" xyz="0 0 0"/>
      <geometry>
        <cylinder length="0.04445" radius="0.0381"/>
      </geometry>
    </collision>
  </link>
  <joint name="left_track_front_wheel_joint" type="continuous">
    <origin rpy="0 0 0" xyz="0.092075 0 -0.028575"/>
    <parent link="left_track_link"/>
    <child link="left_track_front_wheel_link"/>
    <axis xyz="0 1 0"/>
    <anchor xyz="0 0 0"/>
    <limit effort="100" k_velocity="0" velocity="100"/>
    <joint_properties damping="0.0" friction="0.0"/>
  </joint>
  <gazebo reference="left_track_front_wheel_link">
    <mu1 value="100.0"/>
    <mu2 value="100.0"/>
    <kp value="1000000.0"/>
    <kd value="1.0"/>
  </gazebo>
  <gazebo reference="left_track_front_wheel_link">
    <material value="Gazebo/White"/>
  </gazebo>
  <link name="left_track_back_wheel_link">
    <inertial>
      <mass value="0.1"/>
      <origin xyz="0 0 0"/>
      <inertia ixx="0.001" ixy="0.0" ixz="0.0" iyy="0.001" iyz="0.0" izz="0.001"/>
    </inertial>
    <visual>
      <origin rpy="1.57079632679 0 0" xyz="0 0 0"/>
      <geometry>
        <cylinder length="0.04445" radius="0.0381"/>
      </geometry>
      <material name="White"/>
    </visual>
    <collision>
      <origin rpy="1.57079632679 0 0" xyz="0 0 0"/>
      <geometry>
        <cylinder length="0.04445" radius="0.0381"/>
      </geometry>
    </collision>
  </link>
  <joint name="left_track_back_wheel_joint" type="continuous">
    <origin rpy="0 0 0" xyz="-0.092075 0 -0.028575"/>
    <parent link="left_track_link"/>
    <child link="left_track_back_wheel_link"/>
    <axis xyz="0 1 0"/>
    <anchor xyz="0 0 0"/>
    <limit effort="100" k_velocity="0" velocity="100"/>
    <joint_properties damping="0.0" friction="0.0"/>
  </joint>
  <gazebo reference="left_track_back_wheel_link">
    <mu1 value="100.0"/>
    <mu2 value="100.0"/>
    <kp value="1000000.0"/>
    <kd value="1.0"/>
  </gazebo>
  <gazebo reference="left_track_back_wheel_link">
    <material value="Gazebo/White"/>
  </gazebo>
  <link name="left_motor_link">
    <inertial>
      <mass value="3"/>
      <origin xyz="0 0 0"/>
      <inertia ixx="0.01" ixy="0.0" ixz="0.0" iyy="0.01" iyz="0.0" izz="0.01"/>
    </inertial>
    <visual>
      <origin rpy="1.57079632679 0 0" xyz="0 0 0"/>
      <geometry>
        <cylinder length="0.0381" radius="0.018415"/>
      </geometry>
      <material name="LightGrey"/>
    </visual>
    <collision>
      <origin rpy="1.57079632679 0 0" xyz="0 0 0"/>
      <geometry>
        <cylinder length="0.0381" radius="0.018415"/>
      </geometry>
    </collision>
  </link>
  <joint name="left_motor_joint" type="fixed">
    <origin rpy="0 0 0" xyz="-0.0428625 -0.04445 0.028575"/>
    <parent link="left_track_link"/>
    <child link="left_motor_link"/>
  </joint>
  <gazebo reference="left_motor_link">
    <material value="PR2/Grey3"/>
  </gazebo>
  <link name="left_track_motor_wheel_link">
    <inertial>
      <mass value="0.1"/>
      <origin xyz="0 0 0"/>
      <inertia ixx="0.001" ixy="0.0" ixz="0.0" iyy="0.001" iyz="0.0" izz="0.001"/>
    </inertial>
    <visual>
      <origin rpy="1.57079632679 0 0" xyz="0 0 0"/>
      <geometry>
        <cylinder length="0.04445" radius="0.0381"/>
      </geometry>
      <material name="White"/>
    </visual>
    <collision>
      <origin rpy="1.57079632679 0 0" xyz="0 0 0"/>
      <geometry>
        <cylinder length="0.04445" radius="0.0381"/>
      </geometry>
    </collision>
  </link>
  <joint name="left_track_motor_wheel_joint" type="continuous">
    <origin rpy="0 0 0" xyz="0 0.04445 0"/>
    <parent link="left_motor_link"/>
    <child link="left_track_motor_wheel_link"/>
    <axis xyz="0 1 0"/>
    <anchor xyz="0 0 0"/>
    <limit effort="100" k_velocity="0" velocity="100"/>
    <joint_properties damping="0.0" friction="0.0"/>
  </joint>
  <gazebo reference="left_track_motor_wheel_link">
    <mu1 value="100.0"/>
    <mu2 value="100.0"/>
    <kp value="1000000.0"/>
    <kd value="1.0"/>
  </gazebo>
  <gazebo reference="left_track_motor_wheel_link">
    <material value="Gazebo/White"/>
  </gazebo>
  <transmission name="left_track_motor_wheel_trans" type="pr2_mechanism_model/SimpleTransmission">
    <actuator name="left_track_motor_wheel_motor"/>
    <joint name="left_track_motor_wheel_joint"/>
    <mechanicalReduction>1.0</mechanicalReduction>
  </transmission>
  <link name="right_track_link">
    <inertial>
      <mass value="1"/>
      <origin xyz="0 0 0"/>
      <inertia ixx="0.01" ixy="0.0" ixz="0.0" iyy="0.01" iyz="0.0" izz="0.01"/>
    </inertial>
    <visual>
      <origin rpy="0 0 0" xyz="0 0 0"/>
      <geometry>
        <box size="0.22225 0.0508 0.09525"/>
      </geometry>
      <material name="Black"/>
    </visual>
    <collision>
      <origin rpy="0 0 0" xyz="0 0 0"/>
      <geometry>
        <box size="0.22225 0.0508 0.09525"/>
      </geometry>
    </collision>
  </link>
  <joint name="right_track_joint" type="fixed">
    <origin rpy="0 0 0" xyz="0.0428625 -0.117475 0.041275"/>
    <parent link="base_link"/>
    <child link="right_track_link"/>
  </joint>
  <gazebo reference="right_track_link">
    <material value="Gazebo/Grey"/>
  </gazebo>
  <link name="right_track_front_wheel_link">
    <inertial>
      <mass value="0.1"/>
      <origin xyz="0 0 0"/>
      <inertia ixx="0.001" ixy="0.0" ixz="0.0" iyy="0.001" iyz="0.0" izz="0.001"/>
    </inertial>
    <visual>
      <origin rpy="1.57079632679 0 0" xyz="0 0 0"/>
      <geometry>
        <cylinder length="0.04445" radius="0.0381"/>
      </geometry>
      <material name="White"/>
    </visual>
    <collision>
      <origin rpy="1.57079632679 0 0" xyz="0 0 0"/>
      <geometry>
        <cylinder length="0.04445" radius="0.0381"/>
      </geometry>
    </collision>
  </link>
  <joint name="right_track_front_wheel_joint" type="continuous">
    <origin rpy="0 0 0" xyz="0.092075 0 -0.028575"/>
    <parent link="right_track_link"/>
    <child link="right_track_front_wheel_link"/>
    <axis xyz="0 1 0"/>
    <anchor xyz="0 0 0"/>
    <limit effort="100" k_velocity="0" velocity="100"/>
    <joint_properties damping="0.0" friction="0.0"/>
  </joint>
  <gazebo reference="right_track_front_wheel_link">
    <mu1 value="100.0"/>
    <mu2 value="100.0"/>
    <kp value="1000000.0"/>
    <kd value="1.0"/>
  </gazebo>
  <gazebo reference="right_track_front_wheel_link">
    <material value="Gazebo/White"/>
  </gazebo>
  <link name="right_track_back_wheel_link">
    <inertial>
      <mass value="0.1"/>
      <origin xyz="0 0 0"/>
      <inertia ixx="0.001" ixy="0.0" ixz="0.0" iyy="0.001" iyz="0.0" izz="0.001"/>
    </inertial>
    <visual>
      <origin rpy="1.57079632679 0 0" xyz="0 0 0"/>
      <geometry>
        <cylinder length="0.04445" radius="0.0381"/>
      </geometry>
      <material name="White"/>
    </visual>
    <collision>
      <origin rpy="1.57079632679 0 0" xyz="0 0 0"/>
      <geometry>
        <cylinder length="0.04445" radius="0.0381"/>
      </geometry>
    </collision>
  </link>
  <joint name="right_track_back_wheel_joint" type="continuous">
    <origin rpy="0 0 0" xyz="-0.092075 0 -0.028575"/>
    <parent link="right_track_link"/>
    <child link="right_track_back_wheel_link"/>
    <axis xyz="0 1 0"/>
    <anchor xyz="0 0 0"/>
    <limit effort="100" k_velocity="0" velocity="100"/>
    <joint_properties damping="0.0" friction="0.0"/>
  </joint>
  <gazebo reference="right_track_back_wheel_link">
    <mu1 value="100.0"/>
    <mu2 value="100.0"/>
    <kp value="1000000.0"/>
    <kd value="1.0"/>
  </gazebo>
  <gazebo reference="right_track_back_wheel_link">
    <material value="Gazebo/White"/>
  </gazebo>
  <link name="right_motor_link">
    <inertial>
      <mass value="3"/>
      <origin xyz="0 0 0"/>
      <inertia ixx="0.01" ixy="0.0" ixz="0.0" iyy="0.01" iyz="0.0" izz="0.01"/>
    </inertial>
    <visual>
      <origin rpy="1.57079632679 0 0" xyz="0 0 0"/>
      <geometry>
        <cylinder length="0.0381" radius="0.018415"/>
      </geometry>
      <material name="LightGrey"/>
    </visual>
    <collision>
      <origin rpy="1.57079632679 0 0" xyz="0 0 0"/>
      <geometry>
        <cylinder length="0.0381" radius="0.018415"/>
      </geometry>
    </collision>
  </link>
  <joint name="right_motor_joint" type="fixed">
    <origin rpy="0 0 0" xyz="-0.0428625 0.04445 0.028575"/>
    <parent link="right_track_link"/>
    <child link="right_motor_link"/>
  </joint>
  <gazebo reference="right_motor_link">
    <material value="PR2/Grey3"/>
  </gazebo>
  <link name="right_track_motor_wheel_link">
    <inertial>
      <mass value="0.1"/>
      <origin xyz="0 0 0"/>
      <inertia ixx="0.001" ixy="0.0" ixz="0.0" iyy="0.001" iyz="0.0" izz="0.001"/>
    </inertial>
    <visual>
      <origin rpy="1.57079632679 0 0" xyz="0 0 0"/>
      <geometry>
        <cylinder length="0.04445" radius="0.0381"/>
      </geometry>
      <material name="White"/>
    </visual>
    <collision>
      <origin rpy="1.57079632679 0 0" xyz="0 0 0"/>
      <geometry>
        <cylinder length="0.04445" radius="0.0381"/>
      </geometry>
    </collision>
  </link>
  <joint name="right_track_motor_wheel_joint" type="continuous">
    <origin rpy="0 0 0" xyz="0 -0.04445 0"/>
    <parent link="right_motor_link"/>
    <child link="right_track_motor_wheel_link"/>
    <axis xyz="0 1 0"/>
    <anchor xyz="0 0 0"/>
    <limit effort="100" k_velocity="0" velocity="100"/>
    <joint_properties damping="0.0" friction="0.0"/>
  </joint>
  <gazebo reference="right_track_motor_wheel_link">
    <mu1 value="100.0"/>
    <mu2 value="100.0"/>
    <kp value="1000000.0"/>
    <kd value="1.0"/>
  </gazebo>
  <gazebo reference="right_track_motor_wheel_link">
    <material value="Gazebo/White"/>
  </gazebo>
  <transmission name="right_track_motor_wheel_trans" type="pr2_mechanism_model/SimpleTransmission">
    <actuator name="right_track_motor_wheel_motor"/>
    <joint name="right_track_motor_wheel_joint"/>
    <mechanicalReduction>1.0</mechanicalReduction>
  </transmission>
  <gazebo>
    <controller:diffdrive_plugin name="differential_drive_controller" plugin="libdiffdrive_plugin.so">
      <alwaysOn>true</alwaysOn>
      <update>100</update>
      <updateRate>100.0</updateRate>
      <leftJoint>right_track_front_wheel_joint</leftJoint>
      <rightJoint>left_track_front_wheel_joint</rightJoint>
      <wheelSeparation>0.48</wheelSeparation>
      <!-- 0.2413 -->
      <wheelDiameter>0.0762</wheelDiameter>
      <torque>20</torque>
      <interface:position name="position_iface_0"/>
      <robotNamespace>/</robotNamespace>
      <topicName>cmd_vel</topicName>
    </controller:diffdrive_plugin>
    <controller:gazebo_ros_p3d name="p3d_base_controller" plugin="libgazebo_ros_p3d.so">
      <alwaysOn>true</alwaysOn>
      <updateRate>100.0</updateRate>
      <bodyName>base_link</bodyName>
      <topicName>base_pose_ground_truth</topicName>
      <gaussianNoise>0.01</gaussianNoise>
      <frameName>map</frameName>
      <xyzOffsets>0 0 0</xyzOffsets>
      <rpyOffsets>0 0 0</rpyOffsets>
      <interface:position name="p3d_base_position"/>
    </controller:gazebo_ros_p3d>
    <canonicalBody>base_footprint</canonicalBody>
    <!-- this publishes empty joint_states due to no transmission, but
           triggering robot_state_publisher to publish tf between fixed joints in erratic,
           (e.g. base_laser_link for the base_scan frame) -->
    <controller:gazebo_ros_controller_manager name="gazebo_ros_controller_manager" plugin="libgazebo_ros_controller_manager.so">
      <alwaysOn>true</alwaysOn>
      <updateRate>100.0</updateRate>
      <interface:audio name="gazebo_ros_controller_manager_dummy_iface"/>
    </controller:gazebo_ros_controller_manager>
  </gazebo>
  <link name="torso_base_link">
    <inertial>
      <mass value="0.0455"/>
      <origin xyz="0 0 0"/>
      <inertia ixx="0.001" ixy="0.0" ixz="0.0" iyy="0.001" iyz="0.0" izz="0.001"/>
    </inertial>
    <visual>
      <origin rpy="0 0 0" xyz="0 0 0"/>
      <geometry>
        <cylinder length="0.042164" radius="0.04699"/>
      </geometry>
      <material name="Black"/>
    </visual>
    <collision>
      <origin rpy="0 0 0" xyz="0 0 0"/>
      <geometry>
        <cylinder length="0.042164" radius="0.04699"/>
      </geometry>
    </collision>
  </link>
  <joint name="torso_base_joint" type="fixed">
    <origin rpy="0 0 0" xyz="0.0561975 0 0.024257"/>
    <parent link="deck_link"/>
    <child link="torso_base_link"/>
  </joint>
  <gazebo reference="torso_base_link">
    <material value="Gazebo/Grey"/>
  </gazebo>
  <link name="torso_pan_link">
    <inertial>
      <mass value="0.005"/>
      <origin xyz="0 0 0"/>
      <inertia ixx="0.001" ixy="0.0" ixz="0.0" iyy="0.001" iyz="0.0" izz="0.001"/>
    </inertial>
    <visual>
      <origin rpy="0 0 0" xyz="0 0 0.0020193"/>
      <geometry>
        <cylinder length="0.0040386" radius="0.04699"/>
      </geometry>
      <material name="Black"/>
    </visual>
    <collision>
      <origin rpy="0 0 0" xyz="0 0 0.0020193"/>
      <geometry>
        <cylinder length="0.0040386" radius="0.04699"/>
      </geometry>
    </collision>
  </link>
  <joint name="torso_pan_joint" type="revolute">
    <!-- revolute -->
    <origin rpy="0 0 0" xyz="0 0 0.023368"/>
    <parent link="torso_base_link"/>
    <child link="torso_pan_link"/>
    <axis xyz="0 0 1"/>
    <limit effort="0.402072649" lower="-1.57079632679" upper="1.57079632679" velocity="6.544984695"/>
    <dynamics damping="0.1"/>
    <!--joint_properties damping="0.0" friction="0.0" /-->
  </joint>
  <transmission name="torso_pan_trans" type="pr2_mechanism_model/SimpleTransmission">
    <actuator name="torso_pan_motor"/>
    <joint name="torso_pan_joint"/>
    <mechanicalReduction>1.0</mechanicalReduction>
  </transmission>
  <gazebo reference="torso_pan_link">
    <material value="Gazebo/Grey"/>
  </gazebo>
  <link name="torso_lower_servo_link">
    <inertial>
      <mass value="0.0552"/>
      <origin xyz="0 0 0"/>
      <inertia ixx="0.001" ixy="0.0" ixz="0.0" iyy="0.001" iyz="0.0" izz="0.001"/>
    </inertial>
    <visual>
      <origin rpy="0 0 0" xyz="0.0100076 0 0"/>
      <geometry>
        <box size="0.05334 0.037592 0.019558"/>
      </geometry>
      <material name="Black"/>
    </visual>
    <collision>
      <origin rpy="0 0 0" xyz="0.0100076 0 0"/>
      <geometry>
        <box size="0.05334 0.037592 0.019558"/>
      </geometry>
    </collision>
  </link>
  <joint name="torso_lower_servo_joint" type="fixed">
    <origin rpy="0 0 0" xyz="0 0 0.0138176"/>
    <parent link="torso_pan_link"/>
    <child link="torso_lower_servo_link"/>
  </joint>
  <gazebo reference="torso_lower_servo_link">
    <material value="Gazebo/Grey"/>
  </gazebo>
  <link name="torso_lower_tilt_link">
    <inertial>
      <mass value="0.01"/>
      <origin xyz="0 0 0"/>
      <inertia ixx="0.001" ixy="0.0" ixz="0.0" iyy="0.001" iyz="0.0" izz="0.001"/>
    </inertial>
    <visual>
      <origin rpy="0 0 0" xyz="0 0 0.028067"/>
      <geometry>
        <box size="0.024638 0.052832 0.080772"/>
      </geometry>
      <material name="Black"/>
    </visual>
    <collision>
      <origin rpy="0 0 0" xyz="0 0 0.028067"/>
      <geometry>
        <box size="0.024638 0.052832 0.080772"/>
      </geometry>
    </collision>
  </link>
  <joint name="torso_lower_tilt_joint" type="revolute">
    <origin rpy="0 0 0" xyz="0 0 0"/>
    <parent link="torso_lower_servo_link"/>
    <child link="torso_lower_tilt_link"/>
    <axis xyz="0 1 0"/>
    <limit effort="0.941438403" lower="-0.785398163397" upper="0.785398163397" velocity="5.235987756"/>
    <dynamics damping="0.1"/>
    <!--joint_properties damping="0.0" friction="0.0" /-->
  </joint>
  <transmission name="torso_lower_tilt_trans" type="pr2_mechanism_model/SimpleTransmission">
    <actuator name="torso_lower_tilt_motor"/>
    <joint name="torso_lower_tilt_joint"/>
    <mechanicalReduction>1.0</mechanicalReduction>
  </transmission>
  <gazebo reference="torso_lower_tilt_link">
    <material value="Gazebo/Grey"/>
  </gazebo>
  <link name="torso_upper_servo_link">
    <inertial>
      <mass value="0.0552"/>
      <origin xyz="0 0 0"/>
      <inertia ixx="0.001" ixy="0.0" ixz="0.0" iyy="0.001" iyz="0.0" izz="0.001"/>
    </inertial>
    <visual>
      <origin rpy="0 0 0" xyz="0.0100076 0 0"/>
      <geometry>
        <box size="0.05334 0.037592 0.019558"/>
      </geometry>
      <material name="Black"/>
    </visual>
    <collision>
      <origin rpy="0 0 0" xyz="-0.0100076 0 0"/>
      <geometry>
        <box size="0.05334 0.037592 0.019558"/>
      </geometry>
    </collision>
  </link>
  <joint name="torso_upper_servo_joint" type="revolute">
    <!-- revolute -->
    <origin rpy="0 0 0" xyz="0 0 0.058674"/>
    <parent link="torso_lower_tilt_link"/>
    <child link="torso_upper_servo_link"/>
    <axis xyz="0 1 0"/>
    <limit effort="0.941438403" lower="-0.785398163397" upper="0.785398163397" velocity="5.235987756"/>
    <dynamics damping="0.1"/>
    <!--joint_properties damping="0.0" friction="0.0" /-->
  </joint>
  <transmission name="torso_upper_servo_trans" type="pr2_mechanism_model/SimpleTransmission">
    <actuator name="torso_upper_servo_motor"/>
    <joint name="torso_upper_servo_joint"/>
    <mechanicalReduction>1.0</mechanicalReduction>
  </transmission>
  <gazebo reference="torso_upper_servo_link">
    <material value="Gazebo/Grey"/>
  </gazebo>
  <link name="torso_upper_tilt_link">
    <inertial>
      <mass value="0.1"/>
      <origin xyz="0 0 0"/>
      <inertia ixx="0.01" ixy="0.0" ixz="0.0" iyy="0.01" iyz="0.0" izz="0.01"/>
    </inertial>
    <visual>
      <origin rpy="0 0 0" xyz="0 0 0"/>
      <geometry>
        <box size="0.0254 0.0254 0.0762"/>
      </geometry>
      <material name="LightGrey"/>
    </visual>
    <collision>
      <origin rpy="0 0 0" xyz="0 0 0"/>
      <geometry>
        <box size="0.0254 0.0254 0.0762"/>
      </geometry>
    </collision>
  </link>
  <joint name="torso_upper_tilt_joint" type="fixed">
    <origin rpy="0 0 0" xyz="0 0 0.0381"/>
    <parent link="torso_upper_servo_link"/>
    <child link="torso_upper_tilt_link"/>
  </joint>
  <gazebo reference="torso_upper_tilt_link">
    <material value="Gazebo/White"/>
  </gazebo>
  <link name="torso_chest_link">
    <inertial>
      <mass value="0.01"/>
      <origin xyz="0 0 0"/>
      <inertia ixx="0.001" ixy="0.0" ixz="0.0" iyy="0.001" iyz="0.0" izz="0.001"/>
    </inertial>
    <visual>
      <origin rpy="0 0 0" xyz="0 0 0"/>
      <geometry>
        <box size="0.023876 0.0446532 0.041275"/>
      </geometry>
      <material name="Black"/>
    </visual>
    <collision>
      <origin rpy="0 0 0" xyz="0 0 0"/>
      <geometry>
        <box size="0.023876 0.0446532 0.041275"/>
      </geometry>
    </collision>
  </link>
  <joint name="torso_chest_joint" type="fixed">
    <origin rpy="0 0 0" xyz="0.0127 0 0.033655"/>
    <parent link="torso_upper_tilt_link"/>
    <child link="torso_chest_link"/>
  </joint>
  <gazebo reference="torso_chest_link">
    <material value="Gazebo/Grey"/>
  </gazebo>
  <link name="neck_link">
    <inertial>
      <mass value="0.0455"/>
      <origin xyz="0 0 0"/>
      <inertia ixx="0.001" ixy="0.0" ixz="0.0" iyy="0.001" iyz="0.0" izz="0.001"/>
    </inertial>
    <visual>
      <origin rpy="0 0 0" xyz="-0.010287 0 0"/>
      <geometry>
        <box size="0.052832 0.019812 0.041402"/>
      </geometry>
      <material name="Black"/>
    </visual>
    <collision>
      <origin rpy="0 0 0" xyz="-0.010287 0 0"/>
      <geometry>
        <box size="0.052832 0.019812 0.041402"/>
      </geometry>
    </collision>
  </link>
  <joint name="neck_joint" type="fixed">
    <origin rpy="0 0 0" xyz="0 0 0.0681736"/>
    <parent link="torso_upper_tilt_link"/>
    <child link="neck_link"/>
  </joint>
  <gazebo reference="neck_link">
    <material value="Gazebo/Grey"/>
  </gazebo>
  <link name="left_arm_shoulder_link">
    <inertial>
      <mass value="0.0552"/>
      <origin xyz="0 0 0"/>
      <inertia ixx="0.001" ixy="0.0" ixz="0.0" iyy="0.001" iyz="0.0" izz="0.001"/>
    </inertial>
    <visual>
      <origin rpy="0 0 0" xyz="0 0 0"/>
      <geometry>
        <box size="0.019558 0.0468376 0.05334"/>
      </geometry>
      <material name="Black"/>
    </visual>
    <collision>
      <origin rpy="0 0 0" xyz="0 0 0"/>
      <geometry>
        <box size="0.019558 0.0468376 0.05334"/>
      </geometry>
    </collision>
  </link>
  <joint name="left_arm_shoulder_joint" type="fixed">
    <origin rpy="0 0 0" xyz="0 0.0438404 0"/>
    <parent link="torso_chest_link"/>
    <child link="left_arm_shoulder_link"/>
  </joint>
  <gazebo reference="left_arm_shoulder_link">
    <material value="Gazebo/Grey"/>
  </gazebo>
  <link name="left_arm_shoulder_roll_link">
    <inertial>
      <mass value="0.01"/>
      <origin xyz="0 0 0"/>
      <inertia ixx="0.001" ixy="0.0" ixz="0.0" iyy="0.001" iyz="0.0" izz="0.001"/>
    </inertial>
    <visual>
      <origin rpy="0.785398163397 0 0" xyz="0 0.0266065 0.012319"/>
      <geometry>
        <box size="0.052578 0.053213 0.024638"/>
      </geometry>
      <material name="Black"/>
    </visual>
    <collision>
      <origin rpy="0.785398163397 0 0" xyz="0 0.0266065 0.012319"/>
      <geometry>
        <box size="0.052578 0.053213 0.024638"/>
      </geometry>
    </collision>
  </link>
  <joint name="left_arm_shoulder_roll_joint" type="revolute">
    <!-- revolute -->
    <origin rpy="0 0 0" xyz="0 0.0091948 0.0100076"/>
    <parent link="left_arm_shoulder_link"/>
    <child link="left_arm_shoulder_roll_link"/>
    <axis xyz="0 1 0"/>
    <!-- Note: Overtravel limits are 140, -7 degrees instead of 133, 0 -->
    <limit effort="0.941438403" lower="-1.57079632679" upper="1.57079632679" velocity="5.235987756"/>
    <!--safety_controller k_position="100" k_velocity="3" soft_lower_limit="${-2.3213+0.2}" soft_upper_limit="${0.00-0.15}" /-->
    <!--calibration falling="${-1.1606 + cal_r_elbow_flex_flag}"/-->
    <dynamics damping="1.0"/>
  </joint>
  <transmission name="left_arm_shoulder_roll_trans" type="pr2_mechanism_model/SimpleTransmission">
    <actuator name="left_arm_shoulder_roll_motor"/>
    <joint name="left_arm_shoulder_roll_joint"/>
    <mechanicalReduction>1.0</mechanicalReduction>
  </transmission>
  <gazebo reference="left_arm_shoulder_roll_link">
    <material value="Gazebo/Grey"/>
  </gazebo>
  <link name="left_arm_lift_link">
    <inertial>
      <mass value="0.0552"/>
      <origin xyz="0 0 0"/>
      <inertia ixx="0.001" ixy="0.0" ixz="0.0" iyy="0.001" iyz="0.0" izz="0.001"/>
    </inertial>
    <visual>
      <origin rpy="0 0 0" xyz="0 0 -0.0100076"/>
      <geometry>
        <box size="0.0430276 0.019558 0.05334"/>
      </geometry>
      <material name="Black"/>
    </visual>
    <collision>
      <origin rpy="0 0 0" xyz="0 0 -0.0100076"/>
      <geometry>
        <box size="0.0430276 0.019558 0.05334"/>
      </geometry>
    </collision>
  </link>
  <joint name="left_arm_lift_joint" type="revolute">
    <!-- revolute -->
    <origin rpy="0 0 0" xyz="0 0.040894 0.024638"/>
    <parent link="left_arm_shoulder_roll_link"/>
    <child link="left_arm_lift_link"/>
    <axis xyz="1 0 0"/>
    <!-- Note: Overtravel limits are 140, -7 degrees instead of 133, 0 -->
    <limit effort="0.941438403" lower="0.0" upper="3.14159265359" velocity="5.235987756"/>
    <!--safety_controller k_position="100" k_velocity="3" soft_lower_limit="${-2.3213+0.2}" soft_upper_limit="${0.00-0.15}" /-->
    <!--calibration falling="${-1.1606 + cal_r_elbow_flex_flag}"/-->
    <dynamics damping="1.0"/>
  </joint>
  <transmission name="left_arm_lift_trans" type="pr2_mechanism_model/SimpleTransmission">
    <actuator name="left_arm_lift_motor"/>
    <joint name="left_arm_lift_joint"/>
    <mechanicalReduction>1.0</mechanicalReduction>
  </transmission>
  <gazebo reference="left_arm_lift_link">
    <material value="Gazebo/Grey"/>
  </gazebo>
  <link name="left_arm_elbow_link">
    <inertial>
      <mass value="0.0552"/>
      <origin xyz="0 0 0"/>
      <inertia ixx="0.001" ixy="0.0" ixz="0.0" iyy="0.001" iyz="0.0" izz="0.001"/>
    </inertial>
    <visual>
      <origin rpy="0 0 0" xyz="0 0 0"/>
      <geometry>
        <box size="0.05334 0.019558 0.0430276"/>
      </geometry>
      <material name="Black"/>
    </visual>
    <collision>
      <origin rpy="0 0 0" xyz="0 0 0"/>
      <geometry>
        <box size="0.05334 0.019558 0.0430276"/>
      </geometry>
    </collision>
  </link>
  <joint name="left_arm_elbow_joint" type="fixed">
    <origin rpy="0 0 0" xyz="0 0.019558 -0.0183388"/>
    <parent link="left_arm_lift_link"/>
    <child link="left_arm_elbow_link"/>
  </joint>
  <gazebo reference="left_arm_elbow_link">
    <material value="Gazebo/Grey"/>
  </gazebo>
  <link name="left_arm_forearm_link">
    <inertial>
      <mass value="0.01"/>
      <origin xyz="0 0 0"/>
      <inertia ixx="0.001" ixy="0.0" ixz="0.0" iyy="0.001" iyz="0.0" izz="0.001"/>
    </inertial>
    <visual>
      <origin rpy="-0.785398163397 0 0" xyz="0 -0.012319 -0.0266065"/>
      <geometry>
        <box size="0.052578 0.024638 0.053213"/>
      </geometry>
      <material name="Black"/>
    </visual>
    <collision>
      <origin rpy="-0.785398163397 0 0" xyz="0 -0.012319 -0.0266065"/>
      <geometry>
        <box size="0.052578 0.024638 0.053213"/>
      </geometry>
    </collision>
  </link>
  <joint name="left_arm_forearm_joint" type="revolute">
    <!-- revolute -->
    <origin rpy="0 0 0" xyz="0.0100076 0 -0.0091948"/>
    <parent link="left_arm_elbow_link"/>
    <child link="left_arm_forearm_link"/>
    <axis xyz="0 0 1"/>
    <!-- Note: Overtravel limits are 140, -7 degrees instead of 133, 0 -->
    <limit effort="0.941438403" lower="-1.57" upper="1.57" velocity="5.235987756"/>
    <!--safety_controller k_position="100" k_velocity="3" soft_lower_limit="${-2.3213+0.2}" soft_upper_limit="${0.00-0.15}" /-->
    <!--calibration falling="${-1.1606 + cal_r_elbow_flex_flag}"/-->
    <dynamics damping="1.0"/>
  </joint>
  <transmission name="left_arm_forearm_trans" type="pr2_mechanism_model/SimpleTransmission">
    <actuator name="left_arm_forearm_motor"/>
    <joint name="left_arm_forearm_joint"/>
    <mechanicalReduction>1.0</mechanicalReduction>
  </transmission>
  <gazebo reference="left_arm_forearm_link">
    <material value="Gazebo/Grey"/>
  </gazebo>
  <link name="left_arm_hand_link">
    <inertial>
      <mass value="0.0905"/>
      <origin xyz="0 0 0"/>
      <inertia ixx="0.002" ixy="0.0" ixz="0.0" iyy="0.002" iyz="0.0" izz="0.002"/>
    </inertial>
    <visual>
      <origin rpy="0 0 0" xyz="0 0.012446 -0.0099949"/>
      <geometry>
        <box size="0.04318 0.044704 0.053086"/>
      </geometry>
      <material name="Black"/>
    </visual>
    <collision>
      <origin rpy="0 0 0" xyz="0 0.012446 -0.0099949"/>
      <geometry>
        <box size="0.04318 0.044704 0.053086"/>
      </geometry>
    </collision>
  </link>
  <joint name="left_arm_hand_joint" type="revolute">
    <!-- revolute -->
    <origin rpy="0 0 0" xyz="0 -0.0266065 -0.0389255"/>
    <parent link="left_arm_forearm_link"/>
    <child link="left_arm_hand_link"/>
    <axis xyz="1 0 0"/>
    <!-- Note: Overtravel limits are 140, -7 degrees instead of 133, 0 -->
    <limit effort="0.588399" lower="-1.57079632679" upper="0.0" velocity="5.817764173"/>
    <!--safety_controller k_position="100" k_velocity="3" soft_lower_limit="${-2.3213+0.2}" soft_upper_limit="${0.00-0.15}" /-->
    <!--calibration falling="${-1.1606 + cal_r_elbow_flex_flag}"/-->
    <dynamics damping="1.0"/>
  </joint>
  <transmission name="left_arm_hand_trans" type="pr2_mechanism_model/SimpleTransmission">
    <actuator name="left_arm_hand_motor"/>
    <joint name="left_arm_hand_joint"/>
    <mechanicalReduction>1.0</mechanicalReduction>
  </transmission>
  <gazebo reference="left_arm_hand_link">
    <material value="Gazebo/Grey"/>
  </gazebo>
  <link name="left_arm_thumb_link">
    <inertial>
      <mass value="0.001"/>
      <origin xyz="0 0 0"/>
      <inertia ixx="0.001" ixy="0.0" ixz="0.0" iyy="0.001" iyz="0.0" izz="0.001"/>
    </inertial>
    <visual>
      <origin rpy="0 0 0" xyz="0 0.003175 -0.01905"/>
      <geometry>
        <box size="0.0254 0.00635 0.0381"/>
      </geometry>
      <material name="Black"/>
    </visual>
    <collision>
      <origin rpy="0 0 0" xyz="0 0.003175 -0.01905"/>
      <geometry>
        <box size="0.0254 0.00635 0.0381"/>
      </geometry>
    </collision>
  </link>
  <joint name="left_arm_thumb_joint" type="fixed">
    <origin rpy="0 0 0" xyz="0 0 -0.0365379"/>
    <parent link="left_arm_hand_link"/>
    <child link="left_arm_thumb_link"/>
  </joint>
  <gazebo reference="left_arm_hand_link">
    <material value="Gazebo/Grey"/>
  </gazebo>
  <link name="left_arm_fingers_base_link">
    <inertial>
      <mass value="0.001"/>
      <origin xyz="0 0 0"/>
      <inertia ixx="0.001" ixy="0.0" ixz="0.0" iyy="0.001" iyz="0.0" izz="0.001"/>
    </inertial>
    <visual>
      <origin rpy="0 0 0" xyz="0 0 0"/>
      <geometry>
        <box size="0.0508 0.024384 0.024384"/>
      </geometry>
      <material name="Black"/>
    </visual>
    <collision>
      <origin rpy="0 0 0" xyz="0 0 0"/>
      <geometry>
        <box size="0.0508 0.024384 0.024384"/>
      </geometry>
    </collision>
  </link>
  <joint name="left_arm_fingers_base_joint" type="revolute">
    <!-- revolute -->
    <origin rpy="0 0 0" xyz="0 0.0240792 -0.0202819"/>
    <parent link="left_arm_hand_link"/>
    <child link="left_arm_fingers_base_link"/>
    <axis xyz="1 0 0"/>
    <!-- Note: Overtravel limits are 140, -7 degrees instead of 133, 0 -->
    <limit effort="0.402072649" lower="0.0" upper="1.57079632679" velocity="6.544984695"/>
    <!--safety_controller k_position="100" k_velocity="3" soft_lower_limit="${-2.3213+0.2}" soft_upper_limit="${0.00-0.15}" /-->
    <!--calibration falling="${-1.1606 + cal_r_elbow_flex_flag}"/-->
    <dynamics damping="1.0"/>
  </joint>
  <transmission name="left_arm_fingers_base_trans" type="pr2_mechanism_model/SimpleTransmission">
    <actuator name="left_arm_fingers_base_motor"/>
    <joint name="left_arm_fingers_base_joint"/>
    <mechanicalReduction>1.0</mechanicalReduction>
  </transmission>
  <gazebo reference="left_arm_fingers_base_link">
    <material value="Gazebo/Grey"/>
  </gazebo>
  <link name="left_arm_fingers_link">
    <inertial>
      <mass value="0.001"/>
      <origin xyz="0 0 0"/>
      <inertia ixx="0.001" ixy="0.0" ixz="0.0" iyy="0.001" iyz="0.0" izz="0.001"/>
    </inertial>
    <visual>
      <origin rpy="0 0 0" xyz="0 0 0"/>
      <geometry>
        <box size="0.0508 0.00635 0.071882"/>
      </geometry>
      <material name="Black"/>
    </visual>
    <collision>
      <origin rpy="0 0 0" xyz="0 0 0"/>
      <geometry>
        <box size="0.0508 0.00635 0.071882"/>
      </geometry>
    </collision>
  </link>
  <joint name="left_arm_fingers_joint" type="fixed">
    <origin rpy="0 0 0" xyz="0 0.009017 -0.023749"/>
    <parent link="left_arm_fingers_base_link"/>
    <child link="left_arm_fingers_link"/>
  </joint>
  <gazebo reference="left_arm_fingers_link">
    <material value="Gazebo/Grey"/>
  </gazebo>
  <link name="left_arm_finger_tips_link">
    <inertial>
      <mass value="0.001"/>
      <origin xyz="0 0 0"/>
      <inertia ixx="0.001" ixy="0.0" ixz="0.0" iyy="0.001" iyz="0.0" izz="0.001"/>
    </inertial>
    <visual>
      <origin rpy="0 0 0" xyz="0 0 0"/>
      <geometry>
        <box size="0.0508 0.03175 0.00635"/>
      </geometry>
      <material name="Black"/>
    </visual>
    <collision>
      <origin rpy="0 0 0" xyz="0 0 0"/>
      <geometry>
        <box size="0.0508 0.03175 0.00635"/>
      </geometry>
    </collision>
  </link>
  <joint name="left_arm_finger_tips_joint" type="fixed">
    <origin rpy="0 0 0" xyz="0 -0.0127 -0.032766"/>
    <parent link="left_arm_fingers_link"/>
    <child link="left_arm_finger_tips_link"/>
  </joint>
  <gazebo reference="left_arm_finger_tips_link">
    <material value="Gazebo/Grey"/>
  </gazebo>
  <link name="right_arm_shoulder_link">
    <inertial>
      <mass value="0.0552"/>
      <origin xyz="0 0 0"/>
      <inertia ixx="0.001" ixy="0.0" ixz="0.0" iyy="0.001" iyz="0.0" izz="0.001"/>
    </inertial>
    <visual>
      <origin rpy="0 0 0" xyz="0 0 0"/>
      <geometry>
        <box size="0.019558 0.0468376 0.05334"/>
      </geometry>
      <material name="Black"/>
    </visual>
    <collision>
      <origin rpy="0 0 0" xyz="0 0 0"/>
      <geometry>
        <box size="0.019558 0.0468376 0.05334"/>
      </geometry>
    </collision>
  </link>
  <joint name="right_arm_shoulder_joint" type="fixed">
    <origin rpy="0 0 0" xyz="0 -0.0438404 0"/>
    <parent link="torso_chest_link"/>
    <child link="right_arm_shoulder_link"/>
  </joint>
  <gazebo reference="right_arm_shoulder_link">
    <material value="Gazebo/Grey"/>
  </gazebo>
  <link name="right_arm_shoulder_roll_link">
    <inertial>
      <mass value="0.01"/>
      <origin xyz="0 0 0"/>
      <inertia ixx="0.001" ixy="0.0" ixz="0.0" iyy="0.001" iyz="0.0" izz="0.001"/>
    </inertial>
    <visual>
      <origin rpy="-0.785398163397 0 0" xyz="0 -0.0266065 0.012319"/>
      <geometry>
        <box size="0.052578 0.053213 0.024638"/>
      </geometry>
      <material name="Black"/>
    </visual>
    <collision>
      <origin rpy="-0.785398163397 0 0" xyz="0 -0.0266065 0.012319"/>
      <geometry>
        <box size="0.052578 0.053213 0.024638"/>
      </geometry>
    </collision>
  </link>
  <joint name="right_arm_shoulder_roll_joint" type="revolute">
    <!-- revolute -->
    <origin rpy="0 0 0" xyz="0 -0.0091948 0.0100076"/>
    <parent link="right_arm_shoulder_link"/>
    <child link="right_arm_shoulder_roll_link"/>
    <axis xyz="0 1 0"/>
    <!-- Note: Overtravel limits are 140, -7 degrees instead of 133, 0 -->
    <limit effort="0.941438403" lower="-1.57079632679" upper="1.57079632679" velocity="5.235987756"/>
    <!--safety_controller k_position="100" k_velocity="3" soft_lower_limit="${-2.3213+0.2}" soft_upper_limit="${0.00-0.15}" /-->
    <!--calibration falling="${-1.1606 + cal_r_elbow_flex_flag}"/-->
    <dynamics damping="1.0"/>
  </joint>
  <transmission name="right_arm_shoulder_roll_trans" type="pr2_mechanism_model/SimpleTransmission">
    <actuator name="right_arm_shoulder_roll_motor"/>
    <joint name="right_arm_shoulder_roll_joint"/>
    <mechanicalReduction>1.0</mechanicalReduction>
  </transmission>
  <gazebo reference="right_arm_shoulder_roll_link">
    <material value="Gazebo/Grey"/>
  </gazebo>
  <link name="right_arm_lift_link">
    <inertial>
      <mass value="0.0552"/>
      <origin xyz="0 0 0"/>
      <inertia ixx="0.001" ixy="0.0" ixz="0.0" iyy="0.001" iyz="0.0" izz="0.001"/>
    </inertial>
    <visual>
      <origin rpy="0 0 0" xyz="0 0 -0.0100076"/>
      <geometry>
        <box size="0.0430276 0.019558 0.05334"/>
      </geometry>
      <material name="Black"/>
    </visual>
    <collision>
      <origin rpy="0 0 0" xyz="0 0 -0.0100076"/>
      <geometry>
        <box size="0.0430276 0.019558 0.05334"/>
      </geometry>
    </collision>
  </link>
  <joint name="right_arm_lift_joint" type="revolute">
    <!-- revolute -->
    <origin rpy="0 0 0" xyz="0 -0.040894 0.024638"/>
    <parent link="right_arm_shoulder_roll_link"/>
    <child link="right_arm_lift_link"/>
    <axis xyz="1 0 0"/>
    <!-- Note: Overtravel limits are 140, -7 degrees instead of 133, 0 -->
    <limit effort="0.941438403" lower="-3.14159265359" upper="0.0" velocity="5.235987756"/>
    <!--safety_controller k_position="100" k_velocity="3" soft_lower_limit="${-2.3213+0.2}" soft_upper_limit="${0.00-0.15}" /-->
    <!--calibration falling="${-1.1606 + cal_r_elbow_flex_flag}"/-->
    <dynamics damping="1.0"/>
  </joint>
  <transmission name="right_arm_lift_trans" type="pr2_mechanism_model/SimpleTransmission">
    <actuator name="right_arm_lift_motor"/>
    <joint name="right_arm_lift_joint"/>
    <mechanicalReduction>1.0</mechanicalReduction>
  </transmission>
  <gazebo reference="right_arm_lift_link">
    <material value="Gazebo/Grey"/>
  </gazebo>
  <link name="right_arm_elbow_link">
    <inertial>
      <mass value="0.0552"/>
      <origin xyz="0 0 0"/>
      <inertia ixx="0.001" ixy="0.0" ixz="0.0" iyy="0.001" iyz="0.0" izz="0.001"/>
    </inertial>
    <visual>
      <origin rpy="0 0 0" xyz="0 0 0"/>
      <geometry>
        <box size="0.05334 0.019558 0.0430276"/>
      </geometry>
      <material name="Black"/>
    </visual>
    <collision>
      <origin rpy="0 0 0" xyz="0 0 0"/>
      <geometry>
        <box size="0.05334 0.019558 0.0430276"/>
      </geometry>
    </collision>
  </link>
  <joint name="right_arm_elbow_joint" type="fixed">
    <origin rpy="0 0 0" xyz="0 -0.019558 -0.0183388"/>
    <parent link="right_arm_lift_link"/>
    <child link="right_arm_elbow_link"/>
  </joint>
  <gazebo reference="right_arm_elbow_link">
    <material value="Gazebo/Grey"/>
  </gazebo>
  <link name="right_arm_forearm_link">
    <inertial>
      <mass value="0.01"/>
      <origin xyz="0 0 0"/>
      <inertia ixx="0.001" ixy="0.0" ixz="0.0" iyy="0.001" iyz="0.0" izz="0.001"/>
    </inertial>
    <visual>
      <origin rpy="0.785398163397 0 0" xyz="0 0.012319 -0.0266065"/>
      <geometry>
        <box size="0.052578 0.024638 0.053213"/>
      </geometry>
      <material name="Black"/>
    </visual>
    <collision>
      <origin rpy="0.785398163397 0 0" xyz="0 0.012319 -0.0266065"/>
      <geometry>
        <box size="0.052578 0.024638 0.053213"/>
      </geometry>
    </collision>
  </link>
  <joint name="right_arm_forearm_joint" type="revolute">
    <!-- revolute -->
    <origin rpy="0 0 0" xyz="0.0100076 0 -0.0091948"/>
    <parent link="right_arm_elbow_link"/>
    <child link="right_arm_forearm_link"/>
    <axis xyz="0 0 1"/>
    <!-- Note: Overtravel limits are 140, -7 degrees instead of 133, 0 -->
    <limit effort="0.941438403" lower="-1.57" upper="1.57" velocity="5.235987756"/>
    <!--safety_controller k_position="100" k_velocity="3" soft_lower_limit="${-2.3213+0.2}" soft_upper_limit="${0.00-0.15}" /-->
    <!--calibration falling="${-1.1606 + cal_r_elbow_flex_flag}"/-->
    <dynamics damping="1.0"/>
  </joint>
  <transmission name="right_arm_forearm_trans" type="pr2_mechanism_model/SimpleTransmission">
    <actuator name="right_arm_forearm_motor"/>
    <joint name="right_arm_forearm_joint"/>
    <mechanicalReduction>1.0</mechanicalReduction>
  </transmission>
  <gazebo reference="right_arm_forearm_link">
    <material value="Gazebo/Grey"/>
  </gazebo>
  <link name="right_arm_hand_link">
    <inertial>
      <mass value="0.0905"/>
      <origin xyz="0 0 0"/>
      <inertia ixx="0.002" ixy="0.0" ixz="0.0" iyy="0.002" iyz="0.0" izz="0.002"/>
    </inertial>
    <visual>
      <origin rpy="0 0 0" xyz="0 -0.012446 -0.0099949"/>
      <geometry>
        <box size="0.04318 0.044704 0.053086"/>
      </geometry>
      <material name="Black"/>
    </visual>
    <collision>
      <origin rpy="0 0 0" xyz="0 -0.012446 -0.0099949"/>
      <geometry>
        <box size="0.04318 0.044704 0.053086"/>
      </geometry>
    </collision>
  </link>
  <joint name="right_arm_hand_joint" type="revolute">
    <!-- revolute -->
    <origin rpy="0 0 0" xyz="0 0.0266065 -0.0389255"/>
    <parent link="right_arm_forearm_link"/>
    <child link="right_arm_hand_link"/>
    <axis xyz="1 0 0"/>
    <!-- Note: Overtravel limits are 140, -7 degrees instead of 133, 0 -->
    <limit effort="0.588399" lower="0.0" upper="1.57079632679" velocity="5.817764173"/>
    <!--safety_controller k_position="100" k_velocity="3" soft_lower_limit="${-2.3213+0.2}" soft_upper_limit="${0.00-0.15}" /-->
    <!--calibration falling="${-1.1606 + cal_r_elbow_flex_flag}"/-->
    <dynamics damping="1.0"/>
  </joint>
  <transmission name="right_arm_hand_trans" type="pr2_mechanism_model/SimpleTransmission">
    <actuator name="right_arm_hand_motor"/>
    <joint name="right_arm_hand_joint"/>
    <mechanicalReduction>1.0</mechanicalReduction>
  </transmission>
  <gazebo reference="right_arm_hand_link">
    <material value="Gazebo/Grey"/>
  </gazebo>
  <link name="right_arm_thumb_link">
    <inertial>
      <mass value="0.001"/>
      <origin xyz="0 0 0"/>
      <inertia ixx="0.001" ixy="0.0" ixz="0.0" iyy="0.001" iyz="0.0" izz="0.001"/>
    </inertial>
    <visual>
      <origin rpy="0 0 0" xyz="0 -0.003175 -0.01905"/>
      <geometry>
        <box size="0.0254 0.00635 0.0381"/>
      </geometry>
      <material name="Black"/>
    </visual>
    <collision>
      <origin rpy="0 0 0" xyz="0 -0.003175 -0.01905"/>
      <geometry>
        <box size="0.0254 0.00635 0.0381"/>
      </geometry>
    </collision>
  </link>
  <joint name="right_arm_thumb_joint" type="fixed">
    <origin rpy="0 0 0" xyz="0 0 -0.0365379"/>
    <parent link="right_arm_hand_link"/>
    <child link="right_arm_thumb_link"/>
  </joint>
  <gazebo reference="right_arm_hand_link">
    <material value="Gazebo/Grey"/>
  </gazebo>
  <link name="right_arm_fingers_base_link">
    <inertial>
      <mass value="0.001"/>
      <origin xyz="0 0 0"/>
      <inertia ixx="0.001" ixy="0.0" ixz="0.0" iyy="0.001" iyz="0.0" izz="0.001"/>
    </inertial>
    <visual>
      <origin rpy="0 0 0" xyz="0 0 0"/>
      <geometry>
        <box size="0.0508 0.024384 0.024384"/>
      </geometry>
      <material name="Black"/>
    </visual>
    <collision>
      <origin rpy="0 0 0" xyz="0 0 0"/>
      <geometry>
        <box size="0.0508 0.024384 0.024384"/>
      </geometry>
    </collision>
  </link>
  <joint name="right_arm_fingers_base_joint" type="revolute">
    <!-- revolute -->
    <origin rpy="0 0 0" xyz="0 -0.0240792 -0.0202819"/>
    <parent link="right_arm_hand_link"/>
    <child link="right_arm_fingers_base_link"/>
    <axis xyz="1 0 0"/>
    <!-- Note: Overtravel limits are 140, -7 degrees instead of 133, 0 -->
    <limit effort="0.402072649" lower="-1.57079632679" upper="0.0" velocity="6.544984695"/>
    <!--safety_controller k_position="100" k_velocity="3" soft_lower_limit="${-2.3213+0.2}" soft_upper_limit="${0.00-0.15}" /-->
    <!--calibration falling="${-1.1606 + cal_r_elbow_flex_flag}"/-->
    <dynamics damping="1.0"/>
  </joint>
  <transmission name="right_arm_fingers_base_trans" type="pr2_mechanism_model/SimpleTransmission">
    <actuator name="right_arm_fingers_base_motor"/>
    <joint name="right_arm_fingers_base_joint"/>
    <mechanicalReduction>1.0</mechanicalReduction>
  </transmission>
  <gazebo reference="right_arm_fingers_base_link">
    <material value="Gazebo/Grey"/>
  </gazebo>
  <link name="right_arm_fingers_link">
    <inertial>
      <mass value="0.001"/>
      <origin xyz="0 0 0"/>
      <inertia ixx="0.001" ixy="0.0" ixz="0.0" iyy="0.001" iyz="0.0" izz="0.001"/>
    </inertial>
    <visual>
      <origin rpy="0 0 0" xyz="0 0 0"/>
      <geometry>
        <box size="0.0508 0.00635 0.071882"/>
      </geometry>
      <material name="Black"/>
    </visual>
    <collision>
      <origin rpy="0 0 0" xyz="0 0 0"/>
      <geometry>
        <box size="0.0508 0.00635 0.071882"/>
      </geometry>
    </collision>
  </link>
  <joint name="right_arm_fingers_joint" type="fixed">
    <origin rpy="0 0 0" xyz="0 -0.009017 -0.023749"/>
    <parent link="right_arm_fingers_base_link"/>
    <child link="right_arm_fingers_link"/>
  </joint>
  <gazebo reference="right_arm_fingers_link">
    <material value="Gazebo/Grey"/>
  </gazebo>
  <link name="right_arm_finger_tips_link">
    <inertial>
      <mass value="0.001"/>
      <origin xyz="0 0 0"/>
      <inertia ixx="0.001" ixy="0.0" ixz="0.0" iyy="0.001" iyz="0.0" izz="0.001"/>
    </inertial>
    <visual>
      <origin rpy="0 0 0" xyz="0 0 0"/>
      <geometry>
        <box size="0.0508 0.03175 0.00635"/>
      </geometry>
      <material name="Black"/>
    </visual>
    <collision>
      <origin rpy="0 0 0" xyz="0 0 0"/>
      <geometry>
        <box size="0.0508 0.03175 0.00635"/>
      </geometry>
    </collision>
  </link>
  <joint name="right_arm_finger_tips_joint" type="fixed">
    <origin rpy="0 0 0" xyz="0 0.0127 -0.032766"/>
    <parent link="right_arm_fingers_link"/>
    <child link="right_arm_finger_tips_link"/>
  </joint>
  <gazebo reference="right_arm_finger_tips_link">
    <material value="Gazebo/Grey"/>
  </gazebo>
</robot>

